# 예외 처리
## 예외처리(exception handling)
### 프로그램 오류
프로그램이 실행 중 어떠한 원인에 의해서 오작동을 하거나 비정상적으로 종료가 되는 경우가 있다.
이러한 결과를 초래하는 원인을 프로그램 에러 또는 오류라고 한다.
이러한 에러는 발생지점에 따라 **컴파일 에러** 와 **런타임 에러** 로 나뉘고, 이 외에도 논리적 오류가 있다.

- 컴파일 에러(compile-time error)
    - 컴파일 시에 발생하는 에러
    - 컴파일 과정에서 오타나 잘못된 구문, 자료형 체크등을 하며 만약 문제가 발생시 컴파일 에러가 발생한다.
- 런타임 에러 (runtume error)
    - 실행 시에 발생하는 에러
    - 컴파일 과정을 끝내고, 실행 시에 발생하는 프로그램 에러다.
- 논리적 에러 (logical error)
    - 실행은 되지만, 의도한 것과는 다르게 동작하는 에러

런타임 에러는 에러(error)와 예외(exceoption)로 두가지로 나뉜다.

- 에러
    - 프로그램 코드에 의해서 수습될 수 없는 심각한 오류
    - 대표적으로 메모리 부족(OutOfMemoryError)와 스택오버플로우(StackOverflowError)가 있다.
- 예외
    - 프로그램 코드에 의해서 수습될 수 있는 다소 미약한 오류
    - 대표적으로 오버플로우(OverflowError)와 자료형 오류(TypeError)가 있다.

### 예외 클래스의 계층 구조
모든 클래스의 조상인 Object또한, 예외와 에러의 조상이다.
모든 예외의 최고 조상은 Exception클래스이며, 모든 에러의 최고 조상은 Error클래스다.

```markdown
java.lang.Throwable
├── java.lang.Exception  (*일반 예외 - 체크 예외*)
│   ├── IOException
│   ├── SQLException
│   ├── FileNotFoundException
│   ├── ...
│   ├── java.lang.RuntimeException  (*실행 예외 - 언체크 예외*)
│       ├── NullPointerException
│       ├── IndexOutOfBoundsException
│       ├── IllegalArgumentException
│       ├── ArithmeticException
│       ├── ...
│
└── java.lang.Error (*프로그램 복구 불가능한 오류*)
    ├── OutOfMemoryError
    ├── StackOverflowError
    ├── ...

```

다음은 모든 예외와 에러의 조상인 Throwable클래스의 계층도다.
이처럼 예외중에서 큰 2가지 틀로 나뉘면 체크 예외와 언체크 예외로 나뉜다.

- 체크 예외
    - Exception의 자손 중 RuntimeException를 제외한 예외
- 언체크예외
    - RuntimeException을 상속받은 예외

### 예외처리하기 - try - catch문
예외는 프로그래머가 이에 대한 처리를 미리 해주어야 한다.
예외 처리(exception handling)이란, 프로그램 실행 시 발생할 수 있는 예기치 못한 예외의 발생에 대비한 코드를 작성하는 것이며, 예외처리의 목적은 예외의 발생으로 인한 실행 중인 프로그램의 갑작스런 비정상 종료를 막고, 정상적인 실행상태를 유지할 수 있도록 하는 것이다.

- 예외 처리
    - 정의
        - 프로그램 실행 시 발생할 수 있는 예외에 대비한 코드를 작성하는 것
    - 목적
        - 프로그램의 비정상 종료를 막고, 정상적인 실행상태를 유지하는 것

발생한 예외를 처리하지 못하면, 프로그램은 비정상적으로 종료되며, 처리하지 못한 예외(uncaught exception)는 JVM의 예외처리기(UncaughtExceptionHandler)가 받아서 예외의 원인을 화면에 출력한다.

이러한 예외를 다루기 위해, try-catch문을 사용한다.

```java
try {
    //예외가 발생할 가능성이 있는 문장들을 넣는다.
} catch(Exception1 e1) {
    //Exception1이 발생했을 경우, 이를 처리하기 위한 문장을 적는다.
} catch(Exception2 e2) {
    //Exception2가 발생했을 경우, 이를 처리하기 위한 문장을 적는다.
}
```
하나의 try문 구문은 여러 catch문을 넣어 여러 종류의 예외를 처리할 수 있다.

### try-catch문에서의 흐름
- try블럭 내에서 예외가 발생한 경우
    - 발생한 예외와 일치하는 catch블럭이 있는지 확인한다.
    - 일치하는 catch블럭을 찾게 되면, 그 catch블럭 내의 문장들을 수행하고 전체 try-catch문을 빠져나가서 그 다음 문장을 계속해서 수행한다. 만약 일치하는 catch블럭을 찾지 못하면, 예외는 처리되지 못한다.
- try블럭 내에서 예외가 발생하지 않은 경우
    - catch블럭을 거치지 않고 try-catch문을 빠져나가 수행을 계속한다.

### 예외의 발생과 catch블럭
catch블럭은 괄호()와 블럭{} 두 부분으로 나눠져 있는데, 괄호() 내에는 처리하고자 하는 예외와 같은 타입의 참조변수 하나를 선언해야 한다.
예외가 발생하면, 발생한 예외에 해당하는 객체가 만들어 진다.
```java
class ExceptionEx6 {
    public static void main(String args[]) {
        System.out.println(1);
        System.out.println(2);
        try {
            System.out.println(3);
            System.out.println(0 / 0); // 0으로 나눠 ArithmeticException 발생
            System.out.println(4); // 실행되지 않음
        } catch (ArimeticException e) { // ArithmeticException 객체 e 생성
            System.out.println(5);
        }
        // try-catch의 끝
        System.out.println(6);
    }
    // main 메서드의 끝
}
```

#### printStackTrace()와 getMessage()
예외가 발생했을 때 생성되는 예외 클래스의 인스턴스에는 발생한 예외에 대한 정보가 담겨있으며, getMessage()와 printStackTrace()를 통해 이 정보를 얻을 수 있다.

- printStackTrace()
    - 예외발생 당시의 호출스택(Call Stack)에 있던 메서드의 정보와 예외 메세지를 화면에 출력한다
- getMessage()
    - 발생한 예외클래스의 인스턴스에 저장된 메세지를 얻을 수 있다.

#### 멀티 catch블럭
catch구문에서 또한 논리연산자를 사용할 수 있다.
```java
try {
    ...
} catch(Exception1 e1 | Exception2 e2) {
    ...
}
```

여기서 예외클래스 사이에 조상과 자손 관계에 있다면 컴파일에러가 발생한다.

### 예외 발생시키기
키워드 throw를 사용해서 프로그래머가 고의로 예외를 발생시킬 수 있다.
- 연산자 new를 이용해서 발생시키려는 예외 클래스의 객체를 만든다.
    - `Exception e = new Exception("고의로 발생시킴");`
- 키워드 throw를 이용해서 예외를 발생시킨다.
    - `throw e;`

### 메서드에 예외 선언하기
메서드에 예외를 선언하려면, 메서드의 선언부에 키워드 throws를 사용해서 메서드에서 발생할 수 있는 예외를 적어주면 된다.

```java
void method() throws Exception1, Exception2, Exception3 {
    ...
}
```

여기서 조상타입의 Exception클래스를 발생할 수 있는 예외에 적으면, 그 자손타입또한 발생할 수 있다는 점을 주의해야한다.

### finally 블럭
finally 블럭은 예외의 발생여부에 상관없이 실행되어야할 코드를 포함시킬 목적으로 사용된다.
try문이 끝날 때 까지 예외가 발생하지 않으면 finally문으로 가고, 예외가 발생하면 catch문을 거쳐 finally문으로 가게 된다.

```java
try {
    ....
} catch(Exception e) {
    ..
} finally {
    ...
}
```

### 자동 자원 반환 resources문
입출력과 관련된 구문에서, 사용했던 자원을 반환하기 위해서 쓰인다.

```java
try (FileInputStream fis = new FileInputStream("score.dat");
     DataInputStream dis = new DataInputStream(fis)) {
       while (true) {
        score = dis.readInt();
        System.out.println(score);
        sum += score;
    }
} catch (EOFException e) {
    System.out.println("점수의 총합은 " + sum + "입니다.");
} catch (IOException ie) {
    ie.printStackTrace();
}
```

### 사용자 정의 예외
기존에 정의된 예외 클래스 외에 필요에 따라 프로그래머가 새로운 예외 클래스를 정의해야할 때가 있다.
이럴 때 새로운 사용자 정의 예외 클래스를 만든 뒤, 예외 클래스를 상속받으면 된다.

```java
class MyException extends Exeception {
    MyException(String msg) {
        super(msg);
    }
}
```

### 예외 되던지기
예외 되전지기란, 말 그대로로 catch블럭에서 예외를 다시 던지는 기법이다.
몇 개는 try-catch문을 통해서 메서드 내에서 자체적으로 처리하고, 그 나머지는 선언부에 지정하여 호출한 메서드에서 처리하도록 함으로써, 양 쪽에서 나눠서 처리되도록 할 수 있다.
먼저 예외가 발생할 가능성이 있는 메서드에서 try - catch문을 사용해서 예외를 처리해주고 catch문에서 필요한 작업을 행한 후에 throw문을 사용해서 예외를 다시 발생시킨다.
다시 발생한 예외는 이 메서드를 호출한 메서드에게 전달되고, 호출한 메서드의 try-catch문에서 또 다시 처리한다.

```java
public class ExceptionReThrow {
    public static void main(String[] args) {
        try {
            methodA();
        } catch (ArithmeticException e) {
            System.out.println("main에서 예외 처리: " + e.getMessage());
        }
    }

    public static void methodA() {
        try {
            int result = 10 / 0; // ArithmeticException 발생
        } catch (ArithmeticException e) {
            System.out.println("methodA에서 예외 발생, 다시 던짐!");
            throw e; // 예외 되던지기
        }
    }
}

```

### 연결된 예외
한 예외가 다른 예외를 발생시킬 수 있다.
예를 들어 예외 A가 예외 B를 발생시켰다면, A를 B의 "원인 예외(Cause exception)"라고 한다.

```java
public class ChainedExceptionExample {
    public static void main(String[] args) {
        try {
            methodA();
        } catch (Exception e) {
            System.out.println("메인에서 처리된 예외: " + e.getMessage());
            System.out.println("원인 예외: " + e.getCause()); // getCause()로 원인 확인
        }
    }

    public static void methodA() throws Exception {
        try {
            methodB();
        } catch (NullPointerException e) {
            throw new Exception("methodA에서 예외 발생!", e); // 기존 예외(e)를 감싸서 던짐
        }
    }

    public static void methodB() {
        throw new NullPointerException("methodB에서 NullPointerException 발생!"); // 원인 예외
    }
}
```

위 예제가 methodB에서 NullPointerException을 던지고, 이걸 methodA에서 잡아서, 원인 예외를 감싸서 Exception을 main메서드에 던졌다.
